Workbook

Sheet Data Overview
A1: HR Dataset Overview
A3: Dataset Name: | B3: Employee HR Analytics Dataset
A4: Total Records: | B4: 150
A5: Number of Columns: | B5: 15
A6: Date Range: | B6: 2019-01-16 to 2023-12-28
A8: Column Descriptions:
A9: Employee_ID | B9: Unique identifier for each employee
A10: Full_Name | B10: Employee full name
A11: Department | B11: Department where employee works
A12: Position | B12: Job title/position
A13: Location | B13: Work location (office or remote)
A14: Gender | B14: Employee gender
A15: Hire_Date | B15: Date when employee was hired
A16: Years_at_Company | B16: Tenure in years
A17: Annual_Salary | B17: Annual salary in USD
A18: Performance_Score | B18: Performance rating (1-5 scale)
A19: Training_Hours | B19: Annual training hours completed
A20: Overtime_Hours | B20: Monthly overtime hours
... A23: Status | B23: Employment status (Active/Left)
A25: Data Types:
A26: Text Fields | B26: Employee_ID, Full_Name, Department, Position, Location, Gender, Status
A27: Date Fields | B27: Hire_Date
A28: Numeric Fields | B28: Years_at_Company, Annual_Salary, Performance_Score, Training_Hours, Overtime_Hours, Satisfaction_Score, Projects_Completed
A30: Key Observations:
A31: Missing Values | B31: No missing values in this dataset
A32: Duplicates | B32: No duplicate Employee_IDs found
A33: Data Quality | B33: Clean and ready for analysis

Sheet Raw Data
A1: Employee_ID | B1: Full_Name | C1: Department | D1: Position | E1: Location | F1: Gender | G1: Hire_Date | H1: Years_at_Company | I1: Annual_Salary | J1: Performance_Score | K1: Training_Hours | L1: Overtime_Hours | M1: Satisfaction_Score | N1: Projects_Completed | O1: Status
A2: 1001 | B2: Emma Johnson | C2: Operations | D2: Operations Specialist | E2: Remote | F2: Male | G2: 2019-02-21 | H2: 6.7 | I2: 52012 | J2: 3.1 | K2: 17 | L2: 23 | M2: 5 | N2: 22 | O2: Active
A3: 1002 | C3: Finance | D3: Financial Analyst | E3: Remote | F3: Female | G3: 2019-03-07 | H3: 6.6 | I3: 60976 | J3: 2.7 | K3: 29 | L3: 16 | M3: 9 | N3: 1 | O3: Active
A4: 1003 | B4: Sophia Martinez | D4: Marketing Manager | E4: Chicago | F4: Male | G4: 2022-04-21 | H4: 3.5 | I4: 84115 | J4: 4.5 | K4: 0 | L4: 24 | M4: 6 | N4: 23 | O4: Active
A5: 1004 | B5: Daniel Kim | C5: Marketing | E5: New York | F5: Female | G5: 2019-07-29 | H5: 6.3 | I5: 78039 | J5: 3.4 | K5: 45 | L5: 27 | M5: 7 | N5: 20 | O5: Active
A6: 1005 | B6: {='Raw Data'!A2:A152} -> #VALUE! | C6: Finance | D6: Accountant | F6: Male | G6: 2021-02-14 | H6: 4.7 | I6: 52582 | J6: 3.9 | K6: 80 | L6: 19 | M6: 7 | N6: 19 | O6: Active
A7: 1006 | B7: Michael O’Reilly | C7: Operations | D7: Operations Specialist | E7: Chicago | G7: 2023-05-03 | H7: 2.5 | J7: 5 | K7: 29 | L7: 27 | M7: 5 | N7: 13 | O7: Active
A8: 1007 | B8: Chloe Nguyen | C8: IT | D8: IT Manager | E8: Los Angeles | F8: Male | H8: 5.7 | I8: 98748 | J8: 4.3 | K8: 9 | L8: 19 | M8: 10 | N8: 6 | O8: Active
A9: 1008 | B9: Alejandro Torres | C9: HR | D9: HR Manager | E9: Chicago | F9: Female | G9: 2020-07-06 | I9: 88250 | J9: 3 | K9: 41 | L9: 26 | M9: 5 | N9: 8 | O9: Active
A10: 1009 | B10: Haruto Tanaka | C10: IT | D10: Developer | E10: Houston | F10: Male | G10: 2020-03-08 | H10: 5.6 | J10: 4.7 | K10: 40 | L10: 6 | M10: 10 | N10: 16 | O10: Active
A11: 1010 | B11: Olivia Bennett | C11: IT | D11: IT Support | E11: Los Angeles | F11: Female | G11: 2020-05-20 | H11: 5.4 | I11: 58394 | J11: 3.8 | K11: 74 | L11: 13 | M11: 9 | N11: 13 | O11: Active
A12: 1011 | B12: Marcus Dupont | C12: Sales | D12: Sales Rep | E12: Houston | F12: Female | G12: 2023-10-30 | H12: 2 | I12: 43592 | J12: 2.9 | L12: 25 | M12: 10 | N12: 14 | O12: Active
A13: 1012 | B13: Grace Choi | C13: Finance | D13: Financial Analyst | E13: Remote | F13: Female | G13: 2021-12-19 | H13: 3.9 | I13: 68238 | J13: 4.9 | M13: 10 | N13: 4 | O13: Active
A14: 1013 | B14: Ethan Patel | C14: Customer Service | D14: Team Lead | E14: Chicago | F14: Male | G14: 2020-11-27 | H14: 4.9 | I14: 53655 | J14: 3.2 | K14: 20 | L14: 14 | N14: 24 | O14: Active
A15: 1014 | B15: Isabella Romano | C15: Finance | D15: Accountant | E15: Los Angeles | F15: Male | G15: 2023-11-18 | H15: 1.9 | I15: 59779 | J15: 4.6 | K15: 64 | L15: 19 | M15: 6 | O15: Active
A16: 1015 | B16: Lucas Andersen | C16: Finance | D16: Financial Analyst | E16: Remote | F16: Male | G16: 2021-09-27 | H16: 4.1 | I16: 60638 | J16: 2.8 | K16: 46 | L16: 28 | M16: 7 | N16: 8
A17: 1016 | B17: Natalie Brooks | C17: Sales | D17: Sales Director | E17: Remote | F17: Male | G17: 2021-09-22 | H17: 4.1 | I17: 117267 | K17: 68 | L17: 24 | M17: 6 | N17: 5 | O17: Active
A18: 1017 | B18: Amir Khalil | C18: IT | D18: System Admin | E18: Chicago | F18: Female | G18: 2020-03-09 | H18: 5.6 | I18: 77671 | J18: 4.4 | K18: 25 | L18: 22 | M18: 7 | N18: 13 | O18: Active
A19: 1018 | B19: Zoe Richards | C19: Finance | D19: Financial Analyst | E19: Los Angeles | F19: Male | G19: 2019-09-05 | H19: 6.1 | I19: 68123 | J19: 3.1 | K19: 43 | L19: 0 | M19: 9 | N19: 18 | O19: Active
A20: 1019 | B20: Hugo Oliveira | C20: Sales | D20: Sales Director | E20: Chicago | F20: Female | G20: 2022-07-16 | H20: 3.3 | I20: 116929 | J20: 3.1 | K20: 4 | L20: 27 | M20: 7 | N20: 3 | O20: Active
A21: 1020 | B21: Mia Johansson | C21: Marketing | D21: Marketing Director | E21: New York | F21: Female | G21: 2019-09-28 | H21: 6.1 | I21: 143711 | J21: 3.9 | K21: 31 | L21: 25 | M21: 8 | N21: 14 | O21: Active
A22: 1021 | B22: Caleb Wright | C22: IT | D22: System Admin | E22: Houston | F22: Female | G22: 2021-04-21 | H22: 4.5 | I22: 75303 | J22: 0 | K22: 6 | L22: 21 | M22: 10 | N22: 21 | O22: Left
A23: 1022 | B23: Hana Suzuki | C23: Customer Service | D23: CS Rep | E23: Los Angeles | F23: Male | G23: 2020-05-24 | H23: 5.4 | I23: 39278 | J23: 3 | K23: 57 | L23: 4 | M23: 8 | N23: 6 | O23: Active
A24: 1023 | B24: Felix Müller | C24: HR | D24: Recruiter | E24: Los Angeles | F24: Male | G24: 2019-07-20 | H24: 6.3 | I24: 48657 | J24: 4.1 | K24: 69 | L24: 26 | M24: 5 | N24: 3 | O24: Active
A25: 1024 | B25: Layla Carter | C25: HR | D25: HR Manager | F25: Female | G25: 2021-09-12 | H25: 4.1 | I25: 77004 | J25: 4.7 | K25: 7 | L25: 5 | M25: 8 | N25: 1 | O25: Active
A26: 1025 | B26: Noah Singh | C26: IT | D26: System Admin | E26: New York | F26: Male | G26: 2022-11-27 | H26: 2.9 | I26: 78211 | J26: 4.2 | K26: 62 | L26: 4 | M26: 6 | N26: 10 | O26: Active
A27: 1026 | B27: Valentina Costa | C27: Operations | D27: Operations Manager | E27: Remote | F27: Male | G27: 2019-04-28 | H27: 6.5 | I27: 78643 | J27: 4 | K27: 64 | L27: 29 | M27: 9 | N27: 6 | O27: Left
A28: 1027 | B28: Jacob Brown | C28: Customer Service | D28: CS Rep | E28: Remote | F28: Male | G28: 2019-05-21 | H28: 6.4 | I28: 52498 | J28: 2.7 | K28: 30 | L28: 12 | M28: 5 | N28: 19 | O28: Active
A29: 1028 | B29: Emily Zhao | C29: Finance | D29: Accountant | E29: Chicago | F29: Male | G29: 2021-05-08 | H29: 4.5 | I29: 69125 | J29: 3.9 | K29: 40 | L29: 29 | M29: 7 | N29: 7 | O29: Active
A30: 1029 | B30: Mateo Rivera | C30: IT | D30: System Admin | E30: New York | F30: Male | G30: 2019-09-26 | H30: 6.1 | I30: 69830 | J30: 3.6 | K30: 9 | L30: 0 | M30: 8 | N30: 20 | O30: Active
A31: 1030 | B31: Sofia Ivanova | C31: Finance | D31: Accountant | E31: Los Angeles | F31: Female | G31: 2021-11-02 | H31: 4 | I31: 58690 | J31: 2.8 | K31: 44 | L31: 28 | M31: 5 | N31: 8 | O31: Active
A32: 1031 | B32: Benjamin Clark | C32: Customer Service | D32: Team Lead | E32: New York | F32: Male | G32: 2022-12-11 | H32: 2.9 | I32: 59912 | J32: 4 | K32: 67 | L32: 0 | M32: 10 | N32: 18 | O32: Active
A33: 1032 | B33: Priya Sharma | C33: IT | D33: Developer | E33: Chicago | F33: Male | G33: 2023-12-28 | H33: 1.8 | I33: 68507 | J33: 4.4 | K33: 19 | L33: 8 | M33: 7 | N33: 20 | O33: Active
A34: 1033 | B34: Leo Moretti | C34: Operations | D34: Logistics Coordinator | E34: Chicago | F34: Male | G34: 2023-10-13 | H34: 2 | I34: 53650 | J34: 3.8 | K34: 0 | L34: 28 | M34: 5 | N34: 3 | O34: Active
A35: 1034 | B35: Hannah Nguyen | C35: Sales | D35: Sales Manager | E35: Houston | F35: Male | G35: 2023-04-29 | H35: 2.5 | I35: 74286 | J35: 4.1 | K35: 33 | L35: 5 | M35: 10 | N35: 15 | O35: Active
A36: 1035 | B36: Victor Santos | C36: Sales | D36: Sales Rep | E36: New York | F36: Female | G36: 2023-12-14 | H36: 1.9 | I36: 44884 | J36: 3.9 | K36: 47 | L36: 18 | M36: 9 | N36: 5 | O36: Active
A37: 1036 | B37: Ava Reynolds | C37: IT | D37: Developer | E37: Los Angeles | F37: Male | G37: 2021-01-02 | I37: 71883 | J37: 4.2 | K37: 13 | L37: 11 | M37: 9 | N37: 14 | O37: Active
A38: 1037 | B38: Elias Haddad | C38: Customer Service | D38: CS Rep | E38: Houston | F38: Male | G38: 2023-06-27 | H38: 2.3 | I38: 38801 | J38: 4.7 | K38: 3 | L38: 5 | M38: 10 | N38: 11 | O38: Active
A39: 1038 | B39: Jasmine Cooper | D39: IT Support | E39: Houston | F39: Female | G39: 2023-06-01 | H39: 2.4 | I39: 43542 | J39: 3.5 | K39: 4 | L39: 27 | M39: 8 | N39: 8 | O39: Active
A40: 1039 | B40: Chen Wei | C40: IT | D40: IT Support | E40: Chicago | F40: Female | G40: 2020-04-01 | H40: 5.6 | I40: 40775 | J40: 4.2 | K40: 51 | L40: 10 | M40: 7 | N40: 3 | O40: Active
...

Sheet Clean Data
A1: Employee_ID | B1: Full_Name | C1: Department | D1: Position | E1: Location | F1: Gender | G1: Hire_Date | H1: Years_at_Company | I1: Annual_Salary | J1: Performance_Score | K1: Training_Hours | L1: Overtime_Hours | M1: Satisfaction_Score | N1: Projects_Completed | O1: Status
A2: 1001 | B2: Emma Johnson | C2: Operations | D2: Operations Specialist | E2: Remote | F2: Male | G2: 2019-02-21 | H2: 6.7 | I2: 52012 | J2: 3.1 | K2: 17 | L2: 23 | M2: 5 | N2: 22 | O2: Active
A3: =(A2+1) -> 1002 | B3: Unknown | C3: Finance | D3: Financial Analyst | E3: Remote | F3: Female | G3: 2019-03-07 | H3: 6.6 | I3: 60976 | J3: 2.7 | K3: 29 | L3: 16 | M3: 9 | N3: 1 | O3: Active
A4: =(A3+1) -> 1003 | B4: Sophia Martinez | C4: Unknown | D4: Marketing Manager | E4: Chicago | F4: Male | G4: 2022-04-21 | H4: 3.5 | I4: 84115 | J4: 4.5 | K4: =ROUND(AVERAGE(K5:K152), 0) -> 41 | L4: 24 | M4: 6 | N4: 23 | O4: Active
A5: =(A4+1) -> 1004 | B5: Daniel Kim | C5: Marketing | D5: Unknown | E5: New York | F5: Female | G5: 2019-07-29 | H5: 6.3 | I5: 78039 | J5: 3.4 | K5: 45 | L5: 27 | M5: 7 | N5: 20 | O5: Active
A6: =(A5+1) -> 1005 | B6: Aisha Al-Farsi | C6: Finance | D6: Accountant | E6: Unknown | F6: Male | G6: 2021-02-14 | H6: 4.7 | I6: 52582 | J6: 3.9 | K6: 80 | L6: 19 | M6: 7 | N6: 19 | O6: Active
A7: =(A6+1) -> 1006 | B7: Michael O’Reilly | C7: Operations | D7: Operations Specialist | E7: Chicago | F7: Unknown | G7: 2023-05-03 | H7: 2.5 | I7: =ROUND(AVERAGE(I8:I152), 0) -> 71736 | J7: 5 | K7: 29 | L7: 27 | M7: 5 | N7: 13 | O7: Active
A8: =(A7+1) -> 1007 | B8: Chloe Nguyen | C8: IT | D8: IT Manager | E8: Los Angeles | F8: Male | G8: N/A | H8: 5.7 | I8: 98748 | J8: 4.3 | K8: 9 | L8: 19 | M8: 10 | N8: 6 | O8: Active
A9: =(A8+1) -> 1008 | B9: Alejandro Torres | C9: HR | D9: HR Manager | E9: Chicago | F9: Female | G9: 2020-07-06 | H9: =ROUND(AVERAGE(H10:H152), 0) -> 4 | I9: 88250 | J9: 3 | K9: 41 | L9: 26 | M9: 5 | N9: 8 | O9: Active
A10: =(A9+1) -> 1009 | B10: Haruto Tanaka | C10: IT | D10: Developer | E10: Houston | F10: Male | G10: 2020-03-08 | H10: 5.6 | I10: =ROUND(AVERAGE(I11:I152), 0) -> 71431 | J10: 4.7 | K10: 40 | L10: 6 | M10: 10 | N10: 16 | O10: Active
A11: =(A10+1) -> 1010 | B11: Olivia Bennett | C11: IT | D11: IT Support | E11: Los Angeles | F11: Female | G11: 2020-05-20 | H11: 5.4 | I11: 58394 | J11: 3.8 | K11: 74 | L11: 13 | M11: 9 | N11: 13 | O11: Active
A12: =(A11+1) -> 1011 | B12: Marcus Dupont | C12: Sales | D12: Sales Rep | E12: Houston | F12: Female | G12: 2023-10-30 | H12: 2 | I12: 43592 | J12: 2.9 | K12: =ROUND(AVERAGE(K13:K152), 0) -> 40 | L12: 25 | M12: 10 | N12: 14 | O12: Active
A13: =(A12+1) -> 1012 | B13: Grace Choi | C13: Finance | D13: Financial Analyst | E13: Remote | F13: Female | G13: 2021-12-19 | H13: 3.9 | I13: 68238 | J13: 4.9 | K13: =ROUND(AVERAGE(K14:K152), 0) -> 40 | L13: =ROUND(AVERAGE(L14:L152), 0) -> 15 | M13: 10 | N13: 4 | O13: Active
A14: =(A13+1) -> 1013 | B14: Ethan Patel | C14: Customer Service | D14: Team Lead | E14: Chicago | F14: Male | G14: 2020-11-27 | H14: 4.9 | I14: 53655 | J14: 3.2 | K14: 20 | L14: 14 | M14: =ROUND(AVERAGE(M15:M152), 0) -> 8 | N14: 24 | O14: Active
A15: =(A14+1) -> 1014 | B15: Isabella Romano | C15: Finance | D15: Accountant | E15: Los Angeles | F15: Male | G15: 2023-11-18 | H15: 1.9 | I15: 59779 | J15: 4.6 | K15: 64 | L15: 19 | M15: 6 | N15: =ROUND(AVERAGE(N16:N152), 0) -> 14 | O15: Active
A16: =(A15+1) -> 1015 | B16: Lucas Andersen | C16: Finance | D16: Financial Analyst | E16: Remote | F16: Male | G16: 2021-09-27 | H16: 4.1 | I16: 60638 | J16: 2.8 | K16: 46 | L16: 28 | M16: 7 | N16: 8 | O16: N?A
A17: =(A16+1) -> 1016 | B17: Natalie Brooks | C17: Sales | D17: Sales Director | E17: Remote | F17: Male | G17: 2021-09-22 | H17: 4.1 | I17: 117267 | J17: =ROUND(AVERAGE(J18:J152), 0) -> 4 | K17: 68 | L17: 24 | M17: 6 | N17: 5 | O17: Active
A18: =(A17+1) -> 1017 | B18: Amir Khalil | C18: IT | D18: System Admin | E18: Chicago | F18: Female | G18: 2020-03-09 | H18: 5.6 | I18: 77671 | J18: 4.4 | K18: 25 | L18: 22 | M18: 7 | N18: 13 | O18: Active
A19: =(A18+1) -> 1018 | B19: Zoe Richards | C19: Finance | D19: Financial Analyst | E19: Los Angeles | F19: Male | G19: 2019-09-05 | H19: 6.1 | I19: 68123 | J19: 3.1 | K19: 43 | L19: 0 | M19: 9 | N19: 18 | O19: Active
A20: =(A19+1) -> 1019 | B20: Hugo Oliveira | C20: Sales | D20: Sales Director | E20: Chicago | F20: Female | G20: 2022-07-16 | H20: 3.3 | I20: 116929 | J20: 3.1 | K20: 4 | L20: 27 | M20: 7 | N20: 3 | O20: Active
A21: =(A20+1) -> 1020 | B21: Mia Johansson | C21: Marketing | D21: Marketing Director | E21: New York | F21: Female | G21: 2019-09-28 | H21: 6.1 | I21: 143711 | J21: 3.9 | K21: 31 | L21: 25 | M21: 8 | N21: 14 | O21: Active
A22: =(A21+1) -> 1021 | B22: Caleb Wright | C22: IT | D22: System Admin | E22: Houston | F22: Female | G22: 2021-04-21 | H22: 4.5 | I22: 75303 | J22: =ROUND(AVERAGE(J23:J152), 0) -> 4 | K22: 6 | L22: 21 | M22: 10 | N22: 21 | O22: Left
A23: =(A22+1) -> 1022 | B23: Hana Suzuki | C23: Customer Service | D23: CS Rep | E23: Los Angeles | F23: Male | G23: 2020-05-24 | H23: 5.4 | I23: 39278 | J23: 3 | K23: 57 | L23: 4 | M23: 8 | N23: 6 | O23: Active
A24: =(A23+1) -> 1023 | B24: Felix Müller | C24: HR | D24: Recruiter | E24: Los Angeles | F24: Male | G24: 2019-07-20 | H24: 6.3 | I24: 48657 | J24: 4.1 | K24: 69 | L24: 26 | M24: 5 | N24: 3 | O24: Active
A25: =(A24+1) -> 1024 | B25: Layla Carter | C25: HR | D25: HR Manager | E25: Unknown | F25: Female | G25: 2021-09-12 | H25: 4.1 | I25: 77004 | J25: 4.7 | K25: 7 | L25: 5 | M25: 8 | N25: 1 | O25: Active
A26: =(A25+1) -> 1025 | B26: Noah Singh | C26: IT | D26: System Admin | E26: New York | F26: Male | G26: 2022-11-27 | H26: 2.9 | I26: 78211 | J26: 4.2 | K26: 62 | L26: 4 | M26: 6 | N26: 10 | O26: Active
A27: =(A26+1) -> 1026 | B27: Valentina Costa | C27: Operations | D27: Operations Manager | E27: Remote | F27: Male | G27: 2019-04-28 | H27: 6.5 | I27: 78643 | J27: 4 | K27: 64 | L27: 29 | M27: 9 | N27: 6 | O27: Left
A28: =(A27+1) -> 1027 | B28: Jacob Brown | C28: Customer Service | D28: CS Rep | E28: Remote | F28: Male | G28: 2019-05-21 | H28: 6.4 | I28: 52498 | J28: 2.7 | K28: 30 | L28: 12 | M28: 5 | N28: 19 | O28: Active
A29: =(A28+1) -> 1028 | B29: Emily Zhao | C29: Finance | D29: Accountant | E29: Chicago | F29: Male | G29: 2021-05-08 | H29: 4.5 | I29: 69125 | J29: 3.9 | K29: 40 | L29: 29 | M29: 7 | N29: 7 | O29: Active
A30: =(A29+1) -> 1029 | B30: Mateo Rivera | C30: IT | D30: System Admin | E30: New York | F30: Male | G30: 2019-09-26 | H30: 6.1 | I30: 69830 | J30: 3.6 | K30: 9 | L30: 0 | M30: 8 | N30: 20 | O30: Active
A31: =(A30+1) -> 1030 | B31: Sofia Ivanova | C31: Finance | D31: Accountant | E31: Los Angeles | F31: Female | G31: 2021-11-02 | H31: 4 | I31: 58690 | J31: 2.8 | K31: 44 | L31: 28 | M31: 5 | N31: 8 | O31: Active
A32: =(A31+1) -> 1031 | B32: Benjamin Clark | C32: Customer Service | D32: Team Lead | E32: New York | F32: Male | G32: 2022-12-11 | H32: 2.9 | I32: 59912 | J32: 4 | K32: 67 | L32: 0 | M32: 10 | N32: 18 | O32: Active
A33: =(A32+1) -> 1032 | B33: Priya Sharma | C33: IT | D33: Developer | E33: Chicago | F33: Male | G33: 2023-12-28 | H33: 1.8 | I33: 68507 | J33: 4.4 | K33: 19 | L33: 8 | M33: 7 | N33: 20 | O33: Active
A34: =(A33+1) -> 1033 | B34: Leo Moretti | C34: Operations | D34: Logistics Coordinator | E34: Chicago | F34: Male | G34: 2023-10-13 | H34: 2 | I34: 53650 | J34: 3.8 | K34: 0 | L34: 28 | M34: 5 | N34: 3 | O34: Active
... A36: =(A35+1) -> 1035 | B36: Victor Santos | C36: Sales | D36: Sales Rep | E36: New York | F36: Female | G36: 2023-12-14 | H36: 1.9 | I36: 44884 | J36: 3.9 | K36: 47 | L36: 18 | M36: 9 | N36: 5 | O36: Active
A37: =(A36+1) -> 1036 | B37: Ava Reynolds | C37: IT | D37: Developer | E37: Los Angeles | F37: Male | G37: 2021-01-02 | H37: =ROUND(AVERAGE(H38:H152), 0) -> 4 | I37: 71883 | J37: 4.2 | K37: 13 | L37: 11 | M37: 9 | N37: 14 | O37: Active
A38: =(A37+1) -> 1037 | B38: Elias Haddad | C38: Customer Service | D38: CS Rep | E38: Houston | F38: Male | G38: 2023-06-27 | H38: 2.3 | I38: 38801 | J38: 4.7 | K38: 3 | L38: 5 | M38: 10 | N38: 11 | O38: Active
A39: =(A38+1) -> 1038 | B39: Jasmine Cooper | C39: Unknown | D39: IT Support | E39: Houston | F39: Female | G39: 2023-06-01 | H39: 2.4 | I39: 43542 | J39: 3.5 | K39: 4 | L39: 27 | M39: 8 | N39: 8 | O39: Active
A40: =(A39+1) -> 1039 | B40: Chen Wei | C40: IT | D40: IT Support | E40: Chicago | F40: Female | G40: 2020-04-01 | H40: 5.6 | I40: 40775 | J40: 4.2 | K40: 51 | L40: 10 | M40: 7 | N40: 3 | O40: Active
A41: =(A40+1) -> 1040 | B41: Grace Thompson | C41: Operations | D41: Logistics Coordinator | E41: Chicago | F41: Male | G41: 2021-03-29 | H41: 4.6 | I41: 62570 | J41: 3.3 | K41: 3 | L41: 3 | M41: 7 | N41: 6 | O41: Active
...

Sheet Analysis
A1: HR Data Analysis - Key Metrics
A3: BASIC STATISTICS
A5: Total Employees | B5: =COUNTA('Clean Data'!A2:A152) -> 151 | C5: Active and Left
A6: Active Employees | B6: =COUNTIF('Clean Data'!O2:O152,"Active") -> 128
A7: Employees Left | B7: =COUNTIF('Clean Data'!O2:O152,"Left") -> 22
A8: Attrition Rate | B8: =B7/B5 -> 0.14569536 | C8: Percentage who left
A9: Average Salary | B9: =AVERAGE('Clean Data'!I2:I152) -> 71530.57 | C9: All employees
A10: Median Salary | B10: =MEDIAN('Clean Data'!I2:I152) -> 65683
A11: Highest Salary | B11: =MAX('Clean Data'!I2:I152) -> 143711
A12: Lowest Salary | B12: =MIN('Clean Data'!I2:I152) -> 34965 | C12: All employees
A13: Average Tenure | B13: =AVERAGE('Clean Data'!H2:H152) -> 4.2940397 | C13: Years
A14: Avg Performance Score | B14: =AVERAGE('Clean Data'!J2:J152) -> 3.7470199 | C14: Out of 5.0
A15: Avg Satisfaction Score | B15: =AVERAGE('Clean Data'!M2:M152) -> 7.6821192 | C15: Out of 10
A16: Average Tenure | B16: =AVERAGE('Clean Data'!H2:H152) -> 4.2940397 | C16: Years
A18: DEPARTMENT ANALYSIS
A19: Employees in Sales | B19: =COUNTIF('Clean Data'!C2:C152,"Sales") -> 22
A20: Avg Salary - Sales | B20: =AVERAGEIF('Clean Data'!C2:C152,"Sales",'Clean Data'!I2:I152) -> 84279.136
A21: Employees in IT | B21: =COUNTIF('Clean Data'!C2:C152,"IT") -> 21
A22: Avg Salary - IT | B22: =AVERAGEIF('Clean Data'!C2:C152,"IT",'Clean Data'!I2:I152) -> 69426.714
A23: Employees in HR | B23: =COUNTIF('Clean Data'!C2:C152,"HR") -> 27
A24: Avg Salary - HR | B24: =AVERAGEIF('Clean Data'!C2:C152,"HR",'Clean Data'!I2:I152) -> 63286.556
A26: PERFORMANCE METRICS
A27: High Performers (>4.0) | B27: =COUNTIF('Clean Data'!J2:J152,">4") -> 61 | C27: Performance > 4.0
A28: Average Performers (3-4) | B28: =COUNTIFS('Clean Data'!J2:J152,">=3",'Clean Data'!J2:J152,"<=4") -> 64
A29: Low Performers (<3.0) | B29: =COUNTIF('Clean Data'!J2:J152,"<3") -> 26 | C29: Need improvement
A31: TRAINING & DEVELOPMENT
A32: Total Training Hours | B32: =SUM('Clean Data'!K2:K152) -> 6098
A33: Avg Training per Employee | B33: =AVERAGE('Clean Data'!K2:K152) -> 40.384106 | C33: Hours/year
A34: Employees with 50+ Training Hours | B34: =COUNTIF('Clean Data'!K2:K152,">50") -> 57 | C34: Well trained
A36: GENDER DIVERSITY
A37: Male Employees | B37: =COUNTIF('Clean Data'!F2:F152,"Male") -> 76
A38: Female Employees | B38: =COUNTIF('Clean Data'!F2:F152,"Female") -> 73
A39: Gender Ratio (F/M) | B39: =B38/B37 -> 0.96052632
A41: LOCATION ANALYSIS
A42: Remote Workers | B42: =COUNTIF('Clean Data'!E2:E152,"Remote") -> 40
A43: Office Workers | B43: =B5-B42 -> 111 | C43: Total - Remote
A44: % Remote Workers | B44: =B42/B5 -> 0.26490066

Sheet Pivot_Analysis
A1: PIVOT TABLE 1: Department Analysis
A2: Department | B2: Employee_Count | C2: Average Annual Salary | D2: Average Performance Score | E2: Average Satisfaction Score
A3: Customer Service | B3: 22 | C3: 56661 | D3: 3.6136364 | E3: 7.7272727
A4: Finance | B4: 22 | C4: 73125.273 | D4: 3.5136364 | E4: 7.2727273
A5: HR | B5: 27 | C5: 63286.556 | D5: 3.7296296 | E5: 7.5555556
A6: IT | B6: 21 | C6: 69426.714 | D6: 4.0809524 | E6: 8.047619
A7: Marketing | B7: 15 | C7: 90822.333 | D7: 4.1866667 | E7: 7.6666667
A8: Operations | B8: 19 | C8: 68661.211 | D8: 3.4263158 | E8: 6.6842105
A9: Sales | B9: 22 | C9: 84279.136 | D9: 3.7454545 | E9: 8.8181818
A10: Unknown | B10: 3 | C10: 86027 | D10: 4.1 | E10: 7
A11: Total | B11: 151 | C11: 71530.57 | D11: 3.7470199 | E11: 7.6821192
A13: PIVOT TABLE 2: Location Distribution
A14: Row Labels | B14: Count of Employee_ID | C14: Average of Annual_Salary
A15: Chicago | B15: 23 | C15: 73391.522
A16: Houston | B16: 38 | C16: 67565.079
A17: Los Angeles | B17: 28 | C17: 76490.25
A18: New York | B18: 18 | C18: 69996
A19: Remote | B19: 40 | C19: 71892.45
A20: Unknown | B20: 4 | C20: 67071.25
A21: Grand Total | B21: 151 | C21: 71530.57
A23: PIVOT TABLE 3: Performance Distribution
A24: Row Labels | B24: Count of Employee_ID | C24: Average of Annual_Salary
A25: Low performance | B25: 32 | C25: 75084.25
A26: Average Performance | B26: 58 | C26: 67148.81
A27: High Performance | B27: 61 | C27: 73832.607
A28: Grand Total | B28: 151 | C28: 71530.57

Sheet Dashboard
B2: HR ANALYTICS DASHBOARD
B5: Total Employees | F5: Attrition Rate
B6: =(Analysis!B5) -> 151 | F6: =(Analysis!B8) -> 0.14569536
B8: Avg Salary | F8: Avg Performance
B9: =(Analysis!B9) -> 71530.57 | F9: =(Analysis!B14) -> 3.7470199
B12: Department | C12: Employees | D12: Avg Salary
B13: Sales | C13: =COUNTIF('Clean Data'!C2:C152,"Sales") -> 22 | D13: =AVERAGEIF('Clean Data'!C2:C152,"Sales",'Clean Data'!I2:I152) -> 84279.136
B14: Marketing | C14: =COUNTIF('Clean Data'!C2:C152,"Marketing") -> 15 | D14: =AVERAGEIF('Clean Data'!C2:C152,"Marketing",'Clean Data'!I2:I152) -> 90822.333
B15: IT | C15: =COUNTIF('Clean Data'!C2:C152,"IT") -> 21 | D15: =AVERAGEIF('Clean Data'!C2:C152,"IT",'Clean Data'!I2:I152) -> 69426.714
B16: HR | C16: =COUNTIF('Clean Data'!C2:C152,"HR") -> 27 | D16: =AVERAGEIF('Clean Data'!C2:C152,"HR",'Clean Data'!I2:I152) -> 63286.556
B17: Finance | C17: =COUNTIF('Clean Data'!C2:C152,"Finance") -> 22 | D17: =AVERAGEIF('Clean Data'!C2:C152,"Finance",'Clean Data'!I2:I152) -> 73125.273
B18: Operations | C18: =COUNTIF('Clean Data'!C2:C152,"Operations") -> 19 | D18: =AVERAGEIF('Clean Data'!C2:C152,"Operations",'Clean Data'!I2:I152) -> 68661.211
B19: Customer Service | C19: =COUNTIF('Clean Data'!C2:C152,"Customer Service") -> 22 | D19: =AVERAGEIF('Clean Data'!C2:C152,"Customer Service",'Clean Data'!I2:I152) -> 56661
B42: Gender | C42: Count
B43: Male | C43: =COUNTIF('Clean Data'!F2:F152,"Male") -> 76
B44: Female | C44: =COUNTIF('Clean Data'!F2:F152,"Female") -> 73
